Workbook

Sheet Summary
A1: Ocoee, FL | D1: Demographic Summary
A3: Source: Neilson/Claritas | P3: *Claritas 2024
P4: FDG thru Ridgefield (at 5 miles) | S4: United
E5: 1 Mile | H5: 3 Miles | K5: 5 Miles | N5: =+A1 -> Ocoee, FL | P5: Average | Q5: High | R5: Low | S5: States
D6: 2025 | E6: =+D6+5 -> 2030 | F6: % Change | G6: =+D6 -> 2025 | H6: =+E6 -> 2030 | I6: % Change | J6: =+D6 -> 2025 | K6: =+E6 -> 2030 | L6: % Change | N6: =+D6 -> 2025
A7: Adult Children
A8: $100k+ | B8: 45-64 (All CG) | E8: n/a | G8: =+G12+G16 -> 1733 | H8: =+H12+H16 -> 1915 | I8: =+(H8-G8)/G8 -> 0.1050202 | J8: =+J12+J16 -> 4871 | K8: =+K12+K16 -> 5239 | L8: =+(K8-J8)/J8 -> 0.075549169 | N8: =+J8 -> 4871 | P8: 17771.1 | Q8: 32036 | R8: 5494 | S8: n/a
B9: % of All Households | G9: =+G8/'3 mile 2025'!B7 -> 0.17475043 | H9: =+H8/'3 mile 2030'!B7 -> 0.13917151 | J9: =+J8/'5 mile 2025'!B7 -> 0.18779397 | K9: =+K8/'5 mile 2030'!B7 -> 0.1939652 | N9: =+J9 -> 0.18779397 | P9: 0.26963564 | Q9: 0.37247458 | R9: 0.15178222 | S9: 0.1388
B10: % of CG Households | G10: =+G8/('3 mile age of HHer'!H7+'3 mile age of HHer'!J7) -> 0.59635237 | H10: =+H8/('3 mile age of HHer'!H22+'3 mile age of HHer'!J22) -> 0.66080055 | J10: =+J8/('5 mile age of HHer'!H7+'5 mile age of HHer'!J7) -> 0.63424479 | K10: =+K8/('5 mile age of HHer'!H22+'5 mile age of HHer'!J22) -> 0.68753281 | N10: =+J10 -> 0.63424479 | P10: 0.67722554 | Q10: 0.82048984 | R10: 0.39220435 | S10: 0.3661
A12: $100k+ | B12: 45-54 (Younger CG) | E12: n/a | G12: =SUM('3 mile age of HHer'!H15:H18) -> 859 | H12: =SUM('3 mile age of HHer'!H30:H33) -> 1029 | I12: =+(H12-G12)/G12 -> 0.19790454 | J12: =SUM('5 mile age of HHer'!H15:H18) -> 2353 | K12: =SUM('5 mile age of HHer'!H30:H33) -> 2769 | L12: =+(K12-J12)/J12 -> 0.17679558 | N12: =+J12 -> 2353 | P12: 8802.95 | Q12: 17664 | R12: 2466 | S12: n/a
B13: % of All Households | G13: =+G12/'3 mile 2025'!B7 -> 0.086618937 | H13: =+H12/'3 mile 2030'!B7 -> 0.074781977 | J13: =+J12/'5 mile 2025'!B7 -> 0.090716324 | K13: =+K12/'5 mile 2030'!B7 -> 0.10251759 | N13: =+J13 -> 0.090716324 | P13: 0.1300718 | Q13: 0.16718644 | R13: 0.080634938 | S13: 0.072
B14: % of CG Households | G14: =+G12/('3 mile age of HHer'!H7+'3 mile age of HHer'!J7) -> 0.29559532 | H14: =+H12/('3 mile age of HHer'!H22+'3 mile age of HHer'!J22) -> 0.35507246 | J14: =+J12/('5 mile age of HHer'!H7+'5 mile age of HHer'!J7) -> 0.30638021 | K14: =+K12/('5 mile age of HHer'!H22+'5 mile age of HHer'!J22) -> 0.36338583 | N14: =+J14 -> 0.30638021 | P14: 0.32730535 | Q14: 0.38509378 | R14: 0.2083602 | S14: 0.3914
A16: $100k+ | B16: 55-64 (Older CG) | E16: n/a | G16: =SUM('3 mile age of HHer'!J15:J18) -> 874 | H16: =SUM('3 mile age of HHer'!J30:J33) -> 886 | I16: =+(H16-G16)/G16 -> 0.013729977 | J16: =SUM('5 mile age of HHer'!J15:J18) -> 2518 | K16: =SUM('5 mile age of HHer'!J30:J33) -> 2470 | L16: =+(K16-J16)/J16 -> -0.019062748 | N16: =+J16 -> 2518 | P16: 8968.15 | Q16: 16436 | R16: 3028 | S16: n/a
B17: % of All Households | G17: =+G16/'3 mile 2025'!B7 -> 0.088131491 | H17: =+H16/'3 mile 2030'!B7 -> 0.064389535 | J17: =+J16/'5 mile 2025'!B7 -> 0.097077647 | K17: =+K16/'5 mile 2030'!B7 -> 0.091447612 | N17: =+J17 -> 0.097077647 | P17: 0.13956383 | Q17: 0.20528814 | R17: 0.071147285 | S17: 0.0667
B18: % of CG Households | G18: =+G16/('3 mile age of HHer'!H7+'3 mile age of HHer'!J7) -> 0.30075705 | H18: =+H16/('3 mile age of HHer'!H22+'3 mile age of HHer'!J22) -> 0.30572809 | J18: =+J16/('5 mile age of HHer'!H7+'5 mile age of HHer'!J7) -> 0.32786458 | K18: =+K16/('5 mile age of HHer'!H22+'5 mile age of HHer'!J22) -> 0.32414698 | N18: =+J18 -> 0.32786458 | P18: 0.3499202 | Q18: 0.45221027 | R18: 0.18384416 | S18: 0.3423
A20: $75k+ | B20: 45-64 (All CG) | E20: n/a | G20: =+SUM('3 mile age of HHer'!H14:H18)+SUM('3 mile age of HHer'!J14:J18) -> 1983 | H20: =+SUM('3 mile age of HHer'!H29:H33)+SUM('3 mile age of HHer'!J29:J33) -> 2136 | I20: =+(H20-G20)/G20 -> 0.077155825 | J20: =SUM('5 mile age of HHer'!H14:H18)+SUM('5 mile age of HHer'!J14:J18) -> 5494 | K20: =SUM('5 mile age of HHer'!H29:H33)+SUM('5 mile age of HHer'!J29:J33) -> 5826 | L20: =+(K20-J20)/J20 -> 0.06042956 | N20: =+J20 -> 5494 | P20: 20493.1 | Q20: 35797 | R20: 5711 | S20: n/a
B21: % of All Households | G21: =+G20/'3 mile 2025'!B7 -> 0.19995967 | H21: =+H20/'3 mile 2030'!B7 -> 0.15523256 | J21: =+J20/'5 mile 2025'!B7 -> 0.21181278 | K21: =+K20/'5 mile 2030'!B7 -> 0.21569789 | N21: =+J21 -> 0.21181278 | P21: 0.30679236 | Q21: 0.38718644 | R21: 0.21218088 | S21: 0.1885
B22: % of CG Households | G22: =+G20/('3 mile age of HHer'!H7+'3 mile age of HHer'!J7) -> 0.68238128 | H22: =+H20/('3 mile age of HHer'!H22+'3 mile age of HHer'!J22) -> 0.73706004 | J22: =+J20/('5 mile age of HHer'!H7+'5 mile age of HHer'!J7) -> 0.71536458 | K22: =+K20/('5 mile age of HHer'!H22+'5 mile age of HHer'!J22) -> 0.76456693 | N22: =+J22 -> 0.71536458 | P22: 0.77188772 | Q22: 0.8843562 | R22: 0.54827412 | S22: 0.4973
A24: Seniors
A25: $50k+ | B25: 75+ | E25: n/a | G25: =SUM('3 mile age of HHer'!N13:N18)+SUM('3 mile age of HHer'!P13:P18) -> 1067 | H25: =SUM('3 mile age of HHer'!N28:N33)+SUM('3 mile age of HHer'!P28:P33) -> 1300 | I25: =+(H25-G25)/G25 -> 0.21836926 | J25: =SUM('5 mile age of HHer'!N13:N18)+SUM('5 mile age of HHer'!P13:P18) -> 3304 | K25: =SUM('5 mile age of HHer'!N28:N33)+SUM('5 mile age of HHer'!P28:P33) -> 4048 | L25: =+(K25-J25)/J25 -> 0.2251816 | N25: =+J25 -> 3304 | P25: 4567.75 | Q25: 9330 | R25: 1340 | S25: n/a
B26: % of All Households | G26: =+G25/'3 mile 2025'!B7 -> 0.10759302 | H26: =+H25/'3 mile 2030'!B7 -> 0.094476744 | J26: =+J25/'5 mile 2025'!B7 -> 0.12738068 | K26: =+K25/'5 mile 2030'!B7 -> 0.14987042 | N26: =+J26 -> 0.12738068 | P26: 0.070720318 | Q26: 0.11281278 | R26: 0.031110504 | S26: 0.0375
B27: % of Senior Households | G27: =+G25/('3 mile age of HHer'!N7+'3 mile age of HHer'!P7) -> 0.62397661 | H27: =+H25/('3 mile age of HHer'!N22+'3 mile age of HHer'!P22) -> 0.65889508 | J27: =+J25/('5 mile age of HHer'!N7+'5 mile age of HHer'!P7) -> 0.64949872 | K27: =+K25/('5 mile age of HHer'!N22+'5 mile age of HHer'!P22) -> 0.68598543 | N27: =+J27 -> 0.64949872 | P27: 0.54974423 | Q27: 0.64779253 | R27: 0.34528192 | S27: 0.3367
A29: $25k+ | B29: 75+ | E29: n/a | G29: =SUM('3 mile age of HHer'!N11:N18)+SUM('3 mile age of HHer'!P11:P18) -> 1441 | H29: =SUM('3 mile age of HHer'!N26:N33)+SUM('3 mile age of HHer'!P26:P33) -> 1693 | I29: =+(H29-G29)/G29 -> 0.17487856 | J29: =SUM('5 mile age of HHer'!N11:N18)+SUM('5 mile age of HHer'!P11:P18) -> 4370 | K29: =SUM('5 mile age of HHer'!N26:N33)+SUM('5 mile age of HHer'!P26:P33) -> 5175 | L29: =+(K29-J29)/J29 -> 0.18421053 | N29: =+J29 -> 4370 | P29: 6520.15 | Q29: 12896 | R29: 1845 | S29: n/a
B30: % of All Households | G30: =+G29/'3 mile 2025'!B7 -> 0.14530604 | H30: =+H29/'3 mile 2030'!B7 -> 0.12303779 | J30: =+J29/'5 mile 2025'!B7 -> 0.16847868 | K30: =+K29/'5 mile 2030'!B7 -> 0.19159571 | N30: =+J30 -> 0.16847868 | P30: 0.099986087 | Q30: 0.15571839 | R30: 0.044186999 | S30: 0.0713
B31: % of Senior Households | G31: =+G29/('3 mile age of HHer'!N7+'3 mile age of HHer'!P7) -> 0.84269006 | H31: =+H29/('3 mile age of HHer'!N22+'3 mile age of HHer'!P22) -> 0.85808414 | J31: =+J29/('5 mile age of HHer'!N7+'5 mile age of HHer'!P7) -> 0.85905249 | K31: =+K29/('5 mile age of HHer'!N22+'5 mile age of HHer'!P22) -> 0.87697001 | N31: =+J31 -> 0.85905249 | P31: 0.78123131 | Q31: 0.84770086 | R31: 0.61751599 | S31: 0.6404
A33: Affluence
A34: Median Income 45-54 | D34: =+'1 mile age of HHer'!I19 -> 93897 | E34: =+'1 mile age of HHer'!I34 -> 105612.21 | F34: =+(E34-D34)/D34 -> 0.12476661 | G34: =+'3 mile age of HHer'!I19 -> 133805.76 | H34: =+'3 mile age of HHer'!I34 -> 179656.72 | I34: =+(H34-G34)/G34 -> 0.34266806 | J34: =+'5 mile age of HHer'!I19 -> 140224.21 | K34: =+'5 mile age of HHer'!I34 -> 184849.14 | L34: =+(K34-J34)/J34 -> 0.31823984 | N34: =+G34 -> 133805.76 | P34: 182380.17 | Q34: 200000.25 | R34: 94226.49 | S34: 79717
A35: Median Income 55-64 | D35: =+'1 mile age of HHer'!K19 -> 86300.74 | E35: =+'1 mile age of HHer'!K34 -> 93786.89 | F35: =+(E35-D35)/D35 -> 0.086744911 | G35: =+'3 mile age of HHer'!K19 -> 117186.59 | H35: =+'3 mile age of HHer'!K34 -> 141975.19 | I35: =+(H35-G35)/G35 -> 0.21153103 | J35: =+'5 mile age of HHer'!K19 -> 126063.86 | K35: =+'5 mile age of HHer'!K34 -> 144261.42 | L35: =+(K35-J35)/J35 -> 0.14435192 | N35: =+G35 -> 117186.59 | P35: 179223.08 | Q35: 200000.18 | R35: 85014.18 | S35: 69542
A36: Median Income 75-84 | D36: =+'1 mile age of HHer'!O19 -> 88769.28 | E36: =+'1 mile age of HHer'!O34 -> 90531.91 | F36: =+(E36-D36)/D36 -> 0.019856306 | G36: =+'3 mile age of HHer'!O19 -> 81199.5 | H36: =+'3 mile age of HHer'!O34 -> 86801.88 | I36: =+(H36-G36)/G36 -> 0.068995252 | J36: =+'5 mile age of HHer'!O19 -> 80573.88 | K36: =+'5 mile age of HHer'!O34 -> 89588.07 | L36: =+(K36-J36)/J36 -> 0.11187484 | N36: =+G36 -> 81199.5 | P36: 77854.117 | Q36: 104275.43 | R36: 42413.56 | S36: 37421
A37: Median Income 85+ | D37: =+'1 mile age of HHer'!Q19 -> 86976.4 | E37: =+'1 mile age of HHer'!Q34 -> 90678.75 | F37: =+(E37-D37)/D37 -> 0.042567294 | G37: =+'3 mile age of HHer'!Q19 -> 50817.78 | H37: =+'3 mile age of HHer'!Q34 -> 56465.29 | I37: =+(H37-G37)/G37 -> 0.11113256 | J37: =+'5 mile age of HHer'!Q19 -> 62265.04 | K37: =+'5 mile age of HHer'!Q34 -> 69700.58 | L37: =+(K37-J37)/J37 -> 0.11941757 | N37: =+G37 -> 50817.78 | P37: 52332.938 | Q37: 72329.07 | R37: 27758.21 | S37: 28472
A38: Median Income All Ages | D38: =+'1 mile 2025'!C16 -> 84735.21 | E38: =+'1 mile 2030'!C16 -> 90202.44 | F38: =+(E38-D38)/D38 -> 0.064521348 | G38: =+'3 mile 2025'!C16 -> 88794.59 | H38: =+'3 mile 2030'!C16 -> 122411.99 | I38: =+(H38-G38)/G38 -> 0.37859739 | J38: =+'5 mile 2025'!C16 -> 93777.68 | K38: =+'5 mile 2030'!C16 -> 103039.89 | L38: =+(K38-J38)/J38 -> 0.098767745 | N38: =+G38 -> 88794.59 | P38: 122802.28 | Q38: 167842.44 | R38: 67333.32 | S38: 60133
A40: Median Home Value | D40: =+'1 mile 2025'!C18 -> 456584.46 | E40: =+'1 mile 2030'!C18 -> 554623.35 | F40: =+(E40-D40)/D40 -> 0.21472235 | G40: =+'3 mile 2025'!C18 -> 455250.45 | H40: =+'3 mile 2030'!C18 -> 595082.56 | I40: =+(H40-G40)/G40 -> 0.30715425 | J40: =+'5 mile 2025'!C18 -> 506354.79 | K40: =+'5 mile 2030'!C18 -> 587125.59 | L40: =+(K40-J40)/J40 -> 0.15951424 | N40: =+G40 -> 455250.45 | P40: 557705.97 | Q40: 850703.37 | R40: 284294.02 | S40: 207644
A42: Median Age | D42: =+'1 mile 2025'!C14 -> 39.62 | E42: =+'1 mile 2030'!C14 -> 40.88 | F42: =+(E42-D42)/D42 -> 0.03180212 | G42: =+'3 mile 2025'!C14 -> 34.17 | H42: =+'3 mile 2030'!C14 -> 39.62 | I42: =+(H42-G42)/G42 -> 0.15949663 | J42: =+'5 mile 2025'!C14 -> 41.66 | K42: =+'5 mile 2030'!C14 -> 42.84 | L42: =+(K42-J42)/J42 -> 0.028324532 | N42: =+G42 -> 34.17 | P42: 42.381 | Q42: 46.09 | R42: 35.62 | S42: 38.4
D44: =+D6 -> 2025 | E44: =+E6 -> 2030 | F44: % Change | G44: =+G6 -> 2025 | H44: =+H6 -> 2030 | I44: % Change | J44: =+J6 -> 2025 | K44: =+K6 -> 2030 | L44: % Change
E45: =+E5 -> 1 Mile | H45: =+H5 -> 3 Miles | K45: =+K5 -> 5 Miles | N45: =+N5 -> Ocoee, FL | P45: Average | Q45: High | R45: Low | S45: US
A47: =+'1 mile summary tab'!A2 -> Trade Area: 935 Capitol Landing Rd - 1 mi.
A48: =+'3 mile summary'!A2 -> Trade Area: 935 Capitol Landing Rd - 3 mi.
A49: =+'5 mile summary'!A2 -> Trade Area: 935 Capitol Landing Rd - 5 mi.

Sheet PASTE 1 MILE TABS ---->
A1: Coip

Sheet 1 mile summary tab
A1: Pop-Facts® Demographic Quick Facts | Summary
A2: Trade Area: 935 Capitol Landing Rd - 1 mi.
A3: Benchmark: USA
B4: Total | C4: %
A5: Population
A6: 2010 Census | B6: 3138 | C6: 100
A7: 2020 Census | B7: 3585 | C7: 100
A8: 2025 Estimate | B8: 3582 | C8: 100
A9: 2030 Projection | B9: 3498 | C9: 100
A10: Population Growth
A11: Percent Change: 2010 to 2020 | B11: -- | C11: 14.24
A12: Percent Change: 2020 to 2025 | B12: -- | C12: -0.08
A13: Percent Change: 2025 to 2030 | B13: -- | C13: -2.35
A14: Households
A15: 2010 Census | B15: 1342 | C15: 100
A16: 2020 Census | B16: 1572 | C16: 100
A17: 2025 Estimate | B17: 1577 | C17: 100
A18: 2030 Projection | B18: 1539 | C18: 100
A19: Household Growth
A20: Percent Change: 2010 to 2020 | B20: -- | C20: 17.14
A21: Percent Change: 2020 to 2025 | B21: -- | C21: 0.32
A22: Percent Change: 2025 to 2030 | B22: -- | C22: -2.41
A23: Family Households
A24: 2010 Census | B24: 796 | C24: 100
A25: 2020 Census | B25: 906 | C25: 100
A26: 2025 Estimate | B26: 907 | C26: 100
A27: 2030 Projection | B27: 889 | C27: 100
A28: Family Household Growth
A29: Percent Change: 2010 to 2020 | B29: -- | C29: 13.82
A30: Percent Change: 2020 to 2025 | B30: -- | C30: 0.11
A31: Percent Change: 2025 to 2030 | B31: -- | C31: -1.99

Sheet 1 mile demo quick
A1: Pop-Facts® Demographic Quick Facts | Demographic Quick Facts
A2: Trade Area: 935 Capitol Landing Rd - 1 mi.
A3: Benchmark: USA
B4: Total | C4: %
A5: 2025 Est. Population by Single-Classification Race
A6: White Alone | B6: 2100 | C6: 58.63
A7: Black/African American Alone | B7: 699 | C7: 19.51
A8: American Indian/Alaskan Native Alone | B8: 19 | C8: 0.53
A9: Asian Alone | B9: 102 | C9: 2.85
A10: Native Hawaiian/Pacific Islander Alone | B10: 20 | C10: 0.56
A11: Some Other Race Alone | B11: 222 | C11: 6.2
A12: Two or More Races | B12: 420 | C12: 11.72
A13: 2025 Est. Population by Ethnicity
A14: Hispanic/Latino | B14: 465 | C14: 12.98
A15: Not Hispanic/Latino | B15: 3117 | C15: 87.02
A16: 2025 Occupied Housing Units by Tenure
A17: Owner-Occupied | B17: 658 | C17: 41.73
A18: Renter-Occupied | B18: 919 | C18: 58.27
A19: Average Household Size | B19: -- | C19: 2.27
A20: 2025 Households by Household Income
A21: Income < $15,000 | B21: 90 | C21: 5.71
A22: Income $15,000 - $24,999 | B22: 36 | C22: 2.28
A23: Income $25,000 - $34,999 | B23: 116 | C23: 7.36
A24: Income $35,000 - $49,999 | B24: 170 | C24: 10.78
A25: Income $50,000 - $74,999 | B25: 258 | C25: 16.36
A26: Income $75,000 - $99,999 | B26: 294 | C26: 18.64
A27: Income $100,000 - $124,999 | B27: 184 | C27: 11.67
A28: Income $125,000 - $149,999 | B28: 95 | C28: 6.02
A29: Income $150,000 - $199,999 | B29: 128 | C29: 8.12
A30: Income $200,000 - $249,999 | B30: 70 | C30: 4.44
A31: Income $250,000 - $499,999 | B31: 86 | C31: 5.45
A32: Income $500,000+ | B32: 48 | C32: 3.04
A33: Average Household Income | B33: -- | C33: 115897
A34: Median Household Income | B34: -- | C34: 84735.21
A35: 2025 Est. Median HH Income by Single-Classification Race
A36: White Alone | B36: -- | C36: 96783.69
A37: Black/African American Alone | B37: -- | C37: 66769.78
A38: American Indian/Alaskan Native Alone | B38: -- | C38: 66829.83
A39: Asian Alone | B39: -- | C39: 78533.05
A40: Native Hawaiian/Pacific Islander Alone | B40: -- | C40: 87500
...

Sheet 1 mile 2025
A1: Pop-Facts® Effective Buying Income | 2025
A2: Trade Area: 935 Capitol Landing Rd - 1 mi.
A3: Benchmark: USA
B4: Total | C4: %
A5: 2025 Demographic Totals
A6: Population | B6: 3582 | C6: 100
A7: Households | B7: 1577 | C7: 100
A8: Families | B8: 907 | C8: 100
A9: Group Quarters Population | B9: 3 | C9: 0.08
A10: Housing Units | B10: 1715 | C10: 100
A11: 2025 Average Household Size
A12: Average Household Size | B12: -- | C12: 2.27
A13: 2025 Median Age
A14: Median Age | B14: -- | C14: 39.62
A15: 2025 Median Household Income
A16: Median Household Income | B16: -- | C16: 84735.21
A17: 2025 Median All Owner-Occupied Housing Value
A18: Median All Owner-Occupied Housing Value | B18: -- | C18: 456584.46
A19: 2025 Est. Households by Effective Buying Income
A20: CY HHs, EBI < $15,000 | B20: 88 | C20: 5.58
A21: CY HHs, EBI $15,000 - $24,999 | B21: 40 | C21: 2.54
A22: CY HHs, EBI $25,000 - $34,999 | B22: 130 | C22: 8.24
A23: CY HHs, EBI $35,000 - $49,999 | B23: 220 | C23: 13.95
A24: CY HHs, EBI $50,000 - $74,999 | B24: 360 | C24: 22.83
A25: CY HHs, EBI $75,000 - $99,999 | B25: 296 | C25: 18.77
A26: CY HHs, EBI $100,000 - $124,999 | B26: 129 | C26: 8.18
A27: CY HHs, EBI $125,000 - $149,999 | B27: 91 | C27: 5.77
A28: CY HHs, EBI $150,000 - $199,999 | B28: 95 | C28: 6.02
A29: CY HHs, EBI $200,000 - $249,999 | B29: 24 | C29: 1.52
A30: CY HHs, EBI $250,000 - $499,999 | B30: 79 | C30: 5.01
A31: CY HHs, EBI $500,000+ | B31: 25 | C31: 1.58
A32: 2025 Effective Buying Income
A33: Average Effective Buying Income | B33: -- | C33: 97427
A34: Median Effective Buying Income | B34: -- | C34: 71351.99
A35: Aggregate Effective Buying Income | B35: 153645098 | C35: 97428.72

Sheet 1 mile 2030
A1: Pop-Facts® Effective Buying Income | 2030
A2: Trade Area: 935 Capitol Landing Rd - 1 mi.
A3: Benchmark: USA
B4: Total | C4: %
A5: 2030 Demographic Totals
A6: Population | B6: 3498 | C6: 100
A7: Households | B7: 1539 | C7: 100
A8: Families | B8: 889 | C8: 100
A9: Group Quarters Population | B9: 3 | C9: 0.09
A10: Housing Units | B10: 1704 | C10: 100
A11: 2030 Average Household Size
A12: Average Household Size | B12: -- | C12: 2.27
A13: 2030 Median Age
A14: Median Age | B14: -- | C14: 40.88
A15: 2030 Median Household Income
A16: Median Household Income | B16: -- | C16: 90202.44
A17: 2030 Median All Owner-Occupied Housing Value
A18: Median All Owner-Occupied Housing Value | B18: -- | C18: 554623.35
A19: 2030 Proj. Households by Effective Buying Income
A20: FY HHs, EBI < $15,000 | B20: 82 | C20: 5.33
A21: FY HHs, EBI $15,000 - $24,999 | B21: 34 | C21: 2.21
A22: FY HHs, EBI $25,000 - $34,999 | B22: 112 | C22: 7.28
A23: FY HHs, EBI $35,000 - $49,999 | B23: 196 | C23: 12.74
A24: FY HHs, EBI $50,000 - $74,999 | B24: 330 | C24: 21.44
A25: FY HHs, EBI $75,000 - $99,999 | B25: 286 | C25: 18.58
A26: FY HHs, EBI $100,000 - $124,999 | B26: 137 | C26: 8.9
A27: FY HHs, EBI $125,000 - $149,999 | B27: 89 | C27: 5.78
A28: FY HHs, EBI $150,000 - $199,999 | B28: 111 | C28: 7.21
A29: FY HHs, EBI $200,000 - $249,999 | B29: 30 | C29: 1.95
A30: FY HHs, EBI $250,000 - $499,999 | B30: 97 | C30: 6.3
A31: FY HHs, EBI $500,000+ | B31: 34 | C31: 2.21
A32: 2030 Households by Effective Buying Income
A33: Average Household Effective Buying Income | B33: -- | C33: 106730
A34: Median Household Effective Buying Income | B34: -- | C34: 76165.54
A35: Aggregate Household Effective Buying Income | B35: 165221221 | C35: 107356.22

Sheet 1 mile age of HHer
A1: Pop-Facts® Household Income By Age of Householder | Income by Age of Householder
A2: Trade Area: 935 Capitol Landing Rd - 1 mi.
A3: Benchmark: USA
B4: Age 15-24 | D4: Age 25-34 | F4: Age 35-44 | H4: Age 45-54 | J4: Age 55-64 | L4: Age 65-74 | N4: Age 75-84 | P4: Age 85+
B5: HHs | C5: % | D5: HHs | E5: % | F5: HHs | G5: % | H5: HHs | I5: % | J5: HHs | K5: % | L5: HHs | M5: % | N5: HHs | O5: % | P5: HHs | Q5: %
A6: 2025 Household Totals
A7: Household Totals | B7: 87 | C7: 5.52 | D7: 271 | E7: 17.18 | F7: 285 | G7: 18.07 | H7: 226 | I7: 14.33 | J7: 252 | K7: 15.98 | L7: 236 | M7: 14.96 | N7: 168 | O7: 10.65 | P7: 52 | Q7: 3.3
A8: 2025 Estimate Income/Age
A9: Income Less Than $15,000 | B9: 19 | C9: 21.84 | D9: 5 | E9: 1.84 | F9: 4 | G9: 1.4 | H9: 1 | I9: 0.44 | J9: 4 | K9: 1.59 | L9: 22 | M9: 9.32 | N9: 26 | O9: 15.48 | P9: 9 | Q9: 17.31
A10: Income $15,000 - $24,999 | B10: 12 | C10: 13.79 | D10: 7 | E10: 2.58 | F10: 6 | G10: 2.1 | H10: 4 | I10: 1.77 | J10: 3 | K10: 1.19 | L10: 2 | M10: 0.85 | N10: 2 | O10: 1.19 | P10: 1 | Q10: 1.92
A11: Income $25,000 - $34,999 | B11: 1 | C11: 1.15 | D11: 43 | E11: 15.87 | F11: 39 | G11: 13.68 | H11: 4 | I11: 1.77 | J11: 7 | K11: 2.78 | L11: 8 | M11: 3.39 | N11: 8 | O11: 4.76 | P11: 5 | Q11: 9.62
A12: Income $35,000 - $49,999 | B12: 7 | C12: 8.05 | D12: 39 | E12: 14.39 | F12: 33 | G12: 11.58 | H12: 41 | I12: 18.14 | J12: 46 | K12: 18.25 | L12: 2 | M12: 0.85 | N12: 1 | O12: 0.59 | P12: 2 | Q12: 3.85
A13: Income $50,000 - $74,999 | B13: 45 | C13: 51.72 | D13: 54 | E13: 19.93 | F13: 49 | G13: 17.19 | H13: 33 | I13: 14.6 | J13: 43 | K13: 17.06 | L13: 17 | M13: 7.2 | N13: 15 | O13: 8.93 | P13: 2 | Q13: 3.85
A14: Income $75,000 - $99,999 | B14: 0 | C14: 0 | D14: 22 | E14: 8.12 | F14: 25 | G14: 8.77 | H14: 37 | I14: 16.37 | J14: 47 | K14: 18.65 | L14: 91 | M14: 38.56 | N14: 56 | O14: 33.33 | P14: 16 | Q14: 30.77
A15: Income $100,000 - $124,999 | B15: 3 | C15: 3.45 | D15: 62 | E15: 22.88 | F15: 66 | G15: 23.16 | H15: 6 | I15: 2.65 | J15: 7 | K15: 2.78 | L15: 23 | M15: 9.75 | N15: 14 | O15: 8.33 | P15: 3 | Q15: 5.77
A16: Income $125,000 - $149,999 | B16: 0 | C16: 0 | D16: 14 | E16: 5.17 | F16: 20 | G16: 7.02 | H16: 18 | I16: 7.96 | J16: 20 | K16: 7.94 | L16: 11 | M16: 4.66 | N16: 8 | O16: 4.76 | P16: 2 | Q16: 3.85
A17: Income $150,000 - $199,999 | B17: 0 | C17: 0 | D17: 21 | E17: 7.75 | F17: 36 | G17: 12.63 | H17: 27 | I17: 11.95 | J17: 30 | K17: 11.9 | L17: 8 | M17: 3.39 | N17: 5 | O17: 2.98 | P17: 3 | Q17: 5.77
A18: Income $200,000+ | B18: 0 | C18: 0 | D18: 3 | E18: 1.11 | F18: 8 | G18: 2.81 | H18: 55 | I18: 24.34 | J18: 46 | K18: 18.25 | L18: 51 | M18: 21.61 | N18: 32 | O18: 19.05 | P18: 10 | Q18: 19.23
A19: Median HH Income | B19: -- | C19: 53184.74 | D19: -- | E19: 67704.97 | F19: -- | G19: 87894.88 | H19: -- | I19: 93897 | J19: -- | K19: 86300.74 | L19: -- | M19: 92642.1 | N19: -- | O19: 88769.28 | P19: -- | Q19: 86976.4
A20: Average HH Income | B20: -- | C20: 46688 | D20: -- | E20: 87795 | F20: -- | G20: 95278 | H20: -- | I20: 123850 | J20: -- | K20: 111262 | L20: -- | M20: 114008 | N20: -- | O20: 101392 | P20: -- | Q20: 94162
A21: 2030 Household Totals
A22: Household Totals | B22: 64 | C22: 4.16 | D22: 256 | E22: 16.63 | F22: 293 | G22: 19.04 | H22: 235 | I22: 15.27 | J22: 215 | K22: 13.97 | L22: 226 | M22: 14.69 | N22: 195 | O22: 12.67 | P22: 55 | Q22: 3.57
A23: 2030 Projection Income/Age
A24: Income Less Than $15,000 | B24: 9 | C24: 14.06 | D24: 8 | E24: 3.13 | F24: 5 | G24: 1.71 | H24: 1 | I24: 0.43 | J24: 5 | K24: 2.33 | L24: 18 | M24: 7.96 | N24: 29 | O24: 14.87 | P24: 10 | Q24: 18.18
A25: Income $15,000 - $24,999 | B25: 9 | C25: 14.06 | D25: 6 | E25: 2.34 | F25: 6 | G25: 2.05 | H25: 5 | I25: 2.13 | J25: 2 | K25: 0.93 | L25: 2 | M25: 0.89 | N25: 1 | O25: 0.51 | P25: 1 | Q25: 1.82
A26: Income $25,000 - $34,999 | B26: 0 | C26: 0 | D26: 33 | E26: 12.89 | F26: 37 | G26: 12.63 | H26: 4 | I26: 1.7 | J26: 4 | K26: 1.86 | L26: 8 | M26: 3.54 | N26: 8 | O26: 4.1 | P26: 4 | Q26: 7.27
A27: Income $35,000 - $49,999 | B27: 7 | C27: 10.94 | D27: 31 | E27: 12.11 | F27: 36 | G27: 12.29 | H27: 36 | I27: 15.32 | J27: 32 | K27: 14.88 | L27: 3 | M27: 1.33 | N27: 2 | O27: 1.03 | P27: 1 | Q27: 1.82
A28: Income $50,000 - $74,999 | B28: 34 | C28: 53.13 | D28: 48 | E28: 18.75 | F28: 52 | G28: 17.75 | H28: 34 | I28: 14.47 | J28: 36 | K28: 16.74 | L28: 16 | M28: 7.08 | N28: 19 | O28: 9.74 | P28: 4 | Q28: 7.27
A29: Income $75,000 - $99,999 | B29: 0 | C29: 0 | D29: 18 | E29: 7.03 | F29: 20 | G29: 6.83 | H29: 36 | I29: 15.32 | J29: 35 | K29: 16.28 | L29: 81 | M29: 35.84 | N29: 60 | O29: 30.77 | P29: 13 | Q29: 23.64
A30: Income $100,000 - $124,999 | B30: 2 | C30: 3.13 | D30: 60 | E30: 23.44 | F30: 75 | G30: 25.6 | H30: 6 | I30: 2.55 | J30: 4 | K30: 1.86 | L30: 22 | M30: 9.73 | N30: 18 | O30: 9.23 | P30: 3 | Q30: 5.46
A31: Income $125,000 - $149,999 | B31: 2 | C31: 3.13 | D31: 19 | E31: 7.42 | F31: 17 | G31: 5.8 | H31: 23 | I31: 9.79 | J31: 19 | K31: 8.84 | L31: 11 | M31: 4.87 | N31: 10 | O31: 5.13 | P31: 4 | Q31: 7.27
A32: Income $150,000 - $199,999 | B32: 0 | C32: 0 | D32: 27 | E32: 10.55 | F32: 34 | G32: 11.6 | H32: 23 | I32: 9.79 | J32: 28 | K32: 13.02 | L32: 8 | M32: 3.54 | N32: 5 | O32: 2.56 | P32: 3 | Q32: 5.46
A33: Income $200,000+ | B33: 0 | C33: 0 | D33: 6 | E33: 2.34 | F33: 11 | G33: 3.75 | H33: 68 | I33: 28.94 | J33: 50 | K33: 23.26 | L33: 59 | M33: 26.11 | N33: 43 | O33: 22.05 | P33: 14 | Q33: 25.45
A34: Median HH Income | B34: -- | C34: 55438.45 | D34: -- | E34: 77375.31 | F34: -- | G34: 89935.48 | H34: -- | I34: 105612.21 | J34: -- | K34: 93786.89 | L34: -- | M34: 95062.88 | N34: -- | O34: 90531.91 | P34: -- | Q34: 90678.75
A35: Average HH Income | B35: -- | C35: 57502 | D35: -- | E35: 91788 | F35: -- | G35: 101381 | H35: -- | I35: 131973 | J35: -- | K35: 119256 | L35: -- | M35: 120389 | N35: -- | O35: 107243 | P35: -- | Q35: 107424

Sheet PASTE 3 MILE TABS ---->

Sheet 3 mile summary
A1: Pop-Facts® Demographic Quick Facts | Summary
A2: Trade Area: 935 Capitol Landing Rd - 3 mi.
A3: Benchmark: USA
B4: Total | C4: %
A5: Population
A6: 2010 Census | B6: 23460 | C6: 100
A7: 2020 Census | B7: 26913 | C7: 100
A8: 2025 Estimate | B8: 27739 | C8: 100
A9: 2030 Projection | B9: 28302 | C9: 100
A10: Population Growth
A11: Percent Change: 2010 to 2020 | B11: -- | C11: 14.72
A12: Percent Change: 2020 to 2025 | B12: -- | C12: 3.07
A13: Percent Change: 2025 to 2030 | B13: -- | C13: 2.03
A14: Households
A15: 2010 Census | B15: 7961 | C15: 100
A16: 2020 Census | B16: 9443 | C16: 100
A17: 2025 Estimate | B17: 9917 | C17: 100
A18: 2030 Projection | B18: 10181 | C18: 100
A19: Household Growth
A20: Percent Change: 2010 to 2020 | B20: -- | C20: 18.62
A21: Percent Change: 2020 to 2025 | B21: -- | C21: 5.02
A22: Percent Change: 2025 to 2030 | B22: -- | C22: 2.66
A23: Family Households
A24: 2010 Census | B24: 4771 | C24: 100
A25: 2020 Census | B25: 5480 | C25: 100
A26: 2025 Estimate | B26: 5721 | C26: 100
A27: 2030 Projection | B27: 5881 | C27: 100
A28: Family Household Growth
A29: Percent Change: 2010 to 2020 | B29: -- | C29: 14.86
A30: Percent Change: 2020 to 2025 | B30: -- | C30: 4.4
A31: Percent Change: 2025 to 2030 | B31: -- | C31: 2.8

Sheet 3 mile demo quick
A1: Pop-Facts® Demographic Quick Facts | Demographic Quick Facts
A2: Trade Area: 935 Capitol Landing Rd - 3 mi.
A3: Benchmark: USA
B4: Total | C4: %
A5: 2025 Est. Population by Single-Classification Race
A6: White Alone | B6: 14951 | C6: 53.9
A7: Black/African American Alone | B7: 8217 | C7: 29.62
A8: American Indian/Alaskan Native Alone | B8: 78 | C8: 0.28
A9: Asian Alone | B9: 868 | C9: 3.13
A10: Native Hawaiian/Pacific Islander Alone | B10: 47 | C10: 0.17
A11: Some Other Race Alone | B11: 1164 | C11: 4.2
A12: Two or More Races | B12: 2414 | C12: 8.7
A13: 2025 Est. Population by Ethnicity
A14: Hispanic/Latino | B14: 2713 | C14: 9.78
A15: Not Hispanic/Latino | B15: 25026 | C15: 90.22
A16: 2025 Occupied Housing Units by Tenure
A17: Owner-Occupied | B17: 5449 | C17: 54.95
A18: Renter-Occupied | B18: 4468 | C18: 45.05
A19: Average Household Size | B19: -- | C19: 2.23
A20: 2025 Households by Household Income
A21: Income < $15,000 | B21: 521 | C21: 5.25
A22: Income $15,000 - $24,999 | B22: 510 | C22: 5.14
A23: Income $25,000 - $34,999 | B23: 690 | C23: 6.96
A24: Income $35,000 - $49,999 | B24: 994 | C24: 10.02
A25: Income $50,000 - $74,999 | B25: 1596 | C25: 16.09
A26: Income $75,000 - $99,999 | B26: 1112 | C26: 11.21
A27: Income $100,000 - $124,999 | B27: 991 | C27: 9.99
A28: Income $125,000 - $149,999 | B28: 1008 | C28: 10.16
A29: Income $150,000 - $199,999 | B29: 1067 | C29: 10.76
A30: Income $200,000 - $249,999 | B30: 515 | C30: 5.19
A31: Income $250,000 - $499,999 | B31: 598 | C31: 6.03
A32: Income $500,000+ | B32: 315 | C32: 3.18
A33: Average Household Income | B33: -- | C33: 121979
A34: Median Household Income | B34: -- | C34: 88794.59
A35: 2025 Est. Median HH Income by Single-Classification Race
A36: White Alone | B36: -- | C36: 97723.71
A37: Black/African American Alone | B37: -- | C37: 70980.55
A38: American Indian/Alaskan Native Alone | B38: -- | C38: 87794.71
A39: Asian Alone | B39: -- | C39: 49262.36
A40: Native Hawaiian/Pacific Islander Alone | B40: -- | C40: 32907.61
...

Sheet 3 mile 2025
A1: Pop-Facts® Effective Buying Income | 2025
A2: Trade Area: 935 Capitol Landing Rd - 3 mi.
A3: Benchmark: USA
B4: Total | C4: %
A5: 2025 Demographic Totals
A6: Population | B6: 27739 | C6: 100
A7: Households | B7: 9917 | C7: 100
A8: Families | B8: 5721 | C8: 100
A9: Group Quarters Population | B9: 5313 | C9: 19.15
A10: Housing Units | B10: 11315 | C10: 100
A11: 2025 Average Household Size
A12: Average Household Size | B12: -- | C12: 2.23
A13: 2025 Median Age
A14: Median Age | B14: -- | C14: 34.17
A15: 2025 Median Household Income
A16: Median Household Income | B16: -- | C16: 88794.59
A17: 2025 Median All Owner-Occupied Housing Value
A18: Median All Owner-Occupied Housing Value | B18: -- | C18: 455250.45
A19: 2025 Est. Households by Effective Buying Income
A20: CY HHs, EBI < $15,000 | B20: 505 | C20: 5.09
A21: CY HHs, EBI $15,000 - $24,999 | B21: 541 | C21: 5.46
A22: CY HHs, EBI $25,000 - $34,999 | B22: 779 | C22: 7.86
A23: CY HHs, EBI $35,000 - $49,999 | B23: 1291 | C23: 13.02
A24: CY HHs, EBI $50,000 - $74,999 | B24: 1833 | C24: 18.48
A25: CY HHs, EBI $75,000 - $99,999 | B25: 1386 | C25: 13.98
A26: CY HHs, EBI $100,000 - $124,999 | B26: 1245 | C26: 12.55
A27: CY HHs, EBI $125,000 - $149,999 | B27: 753 | C27: 7.59
A28: CY HHs, EBI $150,000 - $199,999 | B28: 713 | C28: 7.19
A29: CY HHs, EBI $200,000 - $249,999 | B29: 168 | C29: 1.69
A30: CY HHs, EBI $250,000 - $499,999 | B30: 538 | C30: 5.42
A31: CY HHs, EBI $500,000+ | B31: 167 | C31: 1.68
A32: 2025 Effective Buying Income
A33: Average Effective Buying Income | B33: -- | C33: 102163
A34: Median Effective Buying Income | B34: -- | C34: 75167.75
A35: Aggregate Effective Buying Income | B35: 1013146730 | C35: 102162.62

Sheet 3 mile 2030
A1: Pop-Facts® Effective Buying Income | 2030
A2: Trade Area: 1234 Williams Rd - 3 mi.
A3: Benchmark: USA
B4: Total | C4: %
A5: 2030 Demographic Totals
A6: Population | B6: 38861 | C6: 100
A7: Households | B7: 13760 | C7: 100
A8: Families | B8: 10654 | C8: 100
A9: Group Quarters Population | B9: 56 | C9: 0.14
A10: Housing Units | B10: 14353 | C10: 100
A11: 2030 Average Household Size
A12: Average Household Size | B12: -- | C12: 2.81
A13: 2030 Median Age
A14: Median Age | B14: -- | C14: 39.62
A15: 2030 Median Household Income
A16: Median Household Income | B16: -- | C16: 122411.99
A17: 2030 Median All Owner-Occupied Housing Value
A18: Median All Owner-Occupied Housing Value | B18: -- | C18: 595082.56
A19: 2030 Proj. Households by Effective Buying Income
A20: FY HHs, EBI < $15,000 | B20: 570 | C20: 4.14
A21: FY HHs, EBI $15,000 - $24,999 | B21: 486 | C21: 3.53
A22: FY HHs, EBI $25,000 - $34,999 | B22: 663 | C22: 4.82
A23: FY HHs, EBI $35,000 - $49,999 | B23: 971 | C23: 7.06
A24: FY HHs, EBI $50,000 - $74,999 | B24: 1940 | C24: 14.1
A25: FY HHs, EBI $75,000 - $99,999 | B25: 2052 | C25: 14.91
A26: FY HHs, EBI $100,000 - $124,999 | B26: 1783 | C26: 12.96
A27: FY HHs, EBI $125,000 - $149,999 | B27: 1483 | C27: 10.78
A28: FY HHs, EBI $150,000 - $199,999 | B28: 1596 | C28: 11.6
A29: FY HHs, EBI $200,000 - $249,999 | B29: 426 | C29: 3.1
A30: FY HHs, EBI $250,000 - $499,999 | B30: 1389 | C30: 10.1
A31: FY HHs, EBI $500,000+ | B31: 402 | C31: 2.92
A32: 2030 Households by Effective Buying Income
A33: Average Household Effective Buying Income | B33: -- | C33: 134907
A34: Median Household Effective Buying Income | B34: -- | C34: 102601.37
A35: Aggregate Household Effective Buying Income | B35: 1859822452 | C35: 135161.52

Sheet 3 mile age of HHer
A1: Pop-Facts® Household Income By Age of Householder | Income by Age of Householder
A2: Trade Area: 935 Capitol Landing Rd - 3 mi.
A3: Benchmark: USA
B4: Age 15-24 | D4: Age 25-34 | F4: Age 35-44 | H4: Age 45-54 | J4: Age 55-64 | L4: Age 65-74 | N4: Age 75-84 | P4: Age 85+
B5: HHs | C5: % | D5: HHs | E5: % | F5: HHs | G5: % | H5: HHs | I5: % | J5: HHs | K5: % | L5: HHs | M5: % | N5: HHs | O5: % | P5: HHs | Q5: %
A6: 2025 Household Totals
A7: Household Totals | B7: 672 | C7: 6.78 | D7: 1422 | E7: 14.34 | F7: 1597 | G7: 16.1 | H7: 1371 | I7: 13.82 | J7: 1535 | K7: 15.48 | L7: 1611 | M7: 16.25 | N7: 1151 | O7: 11.61 | P7: 559 | Q7: 5.64
A8: 2025 Estimate Income/Age
A9: Income Less Than $15,000 | B9: 205 | C9: 30.51 | D9: 46 | E9: 3.23 | F9: 34 | G9: 2.13 | H9: 15 | I9: 1.09 | J9: 31 | K9: 2.02 | L9: 66 | M9: 4.1 | N9: 74 | O9: 6.43 | P9: 50 | Q9: 8.95
A10: Income $15,000 - $24,999 | B10: 68 | C10: 10.12 | D10: 70 | E10: 4.92 | F10: 51 | G10: 3.19 | H10: 43 | I10: 3.14 | J10: 59 | K10: 3.84 | L10: 73 | M10: 4.53 | N10: 79 | O10: 6.86 | P10: 68 | Q10: 12.16
A11: Income $25,000 - $34,999 | B11: 49 | C11: 7.29 | D11: 133 | E11: 9.35 | F11: 96 | G11: 6.01 | H11: 27 | I11: 1.97 | J11: 46 | K11: 3 | L11: 120 | M11: 7.45 | N11: 128 | O11: 11.12 | P11: 91 | Q11: 16.28
A12: Income $35,000 - $49,999 | B12: 150 | C12: 22.32 | D12: 166 | E12: 11.67 | F12: 138 | G12: 8.64 | H12: 132 | I12: 9.63 | J12: 155 | K12: 10.1 | L12: 99 | M12: 6.14 | N12: 87 | O12: 7.56 | P12: 68 | Q12: 12.16
A13: Income $50,000 - $74,999 | B13: 88 | C13: 13.1 | D13: 335 | E13: 23.56 | F13: 309 | G13: 19.35 | H13: 187 | I13: 13.64 | J13: 228 | K13: 14.85 | L13: 213 | M13: 13.22 | N13: 163 | O13: 14.16 | P13: 74 | Q13: 13.24
A14: Income $75,000 - $99,999 | B14: 39 | C14: 5.8 | D14: 165 | E14: 11.6 | F14: 156 | G14: 9.77 | H14: 108 | I14: 7.88 | J14: 142 | K14: 9.25 | L14: 265 | M14: 16.45 | N14: 174 | O14: 15.12 | P14: 64 | Q14: 11.45
A15: Income $100,000 - $124,999 | B15: 50 | C15: 7.44 | D15: 162 | E15: 11.39 | F15: 205 | G15: 12.84 | H15: 128 | I15: 9.34 | J15: 153 | K15: 9.97 | L15: 168 | M15: 10.43 | N15: 96 | O15: 8.34 | P15: 29 | Q15: 5.19
A16: Income $125,000 - $149,999 | B16: 2 | C16: 0.3 | D16: 179 | E16: 12.59 | F16: 286 | G16: 17.91 | H16: 129 | I16: 9.41 | J16: 128 | K16: 8.34 | L16: 164 | M16: 10.18 | N16: 90 | O16: 7.82 | P16: 29 | Q16: 5.19
A17: Income $150,000 - $199,999 | B17: 21 | C17: 3.13 | D17: 118 | E17: 8.3 | F17: 212 | G17: 13.28 | H17: 249 | I17: 18.16 | J17: 245 | K17: 15.96 | L17: 133 | M17: 8.26 | N17: 71 | O17: 6.17 | P17: 19 | Q17: 3.4
A18: Income $200,000+ | B18: 1 | C18: 0.15 | D18: 49 | E18: 3.45 | F18: 109 | G18: 6.83 | H18: 353 | I18: 25.75 | J18: 348 | K18: 22.67 | L18: 311 | M18: 19.3 | N18: 190 | O18: 16.51 | P18: 68 | Q18: 12.16
A19: Median HH Income | B19: -- | C19: 36716.02 | D19: -- | E19: 71651.46 | F19: -- | G19: 101956.12 | H19: -- | I19: 133805.76 | J19: -- | K19: 117186.59 | L19: -- | M19: 96867.21 | N19: -- | O19: 81199.5 | P19: -- | Q19: 50817.78
A20: Average HH Income | B20: -- | C20: 47672 | D20: -- | E20: 93360 | F20: -- | G20: 108347 | H20: -- | I20: 143474 | J20: -- | K20: 127701 | L20: -- | M20: 114814 | N20: -- | O20: 98548 | P20: -- | Q20: 86988
A21: 2030 Household Totals
A22: Household Totals | B22: 602 | C22: 5.91 | D22: 1353 | E22: 13.29 | F22: 1706 | G22: 16.76 | H22: 1527 | I22: 15 | J22: 1371 | K22: 13.47 | L22: 1650 | M22: 16.21 | N22: 1351 | O22: 13.27 | P22: 622 | Q22: 6.11
A23: 2030 Projection Income/Age
A24: Income Less Than $15,000 | B24: 174 | C24: 28.9 | D24: 44 | E24: 3.25 | F24: 38 | G24: 2.23 | H24: 16 | I24: 1.05 | J24: 25 | K24: 1.82 | L24: 62 | M24: 3.76 | N24: 84 | O24: 6.22 | P24: 54 | Q24: 8.68
A25: Income $15,000 - $24,999 | B25: 55 | C25: 9.14 | D25: 57 | E25: 4.21 | F25: 50 | G25: 2.93 | H25: 41 | I25: 2.69 | J25: 39 | K25: 2.85 | L25: 60 | M25: 3.64 | N25: 77 | O25: 5.7 | P25: 65 | Q25: 10.45
A26: Income $25,000 - $34,999 | B26: 50 | C26: 8.31 | D26: 113 | E26: 8.35 | F26: 98 | G26: 5.74 | H26: 22 | I26: 1.44 | J26: 30 | K26: 2.19 | L26: 102 | M26: 6.18 | N26: 126 | O26: 9.33 | P26: 88 | Q26: 14.15
A27: Income $35,000 - $49,999 | B27: 133 | C27: 22.09 | D27: 166 | E27: 12.27 | F27: 145 | G27: 8.5 | H27: 126 | I27: 8.25 | J27: 105 | K27: 7.66 | L27: 103 | M27: 6.24 | N27: 100 | O27: 7.4 | P27: 79 | Q27: 12.7
A28: Income $50,000 - $74,999 | B28: 80 | C28: 13.29 | D28: 292 | E28: 21.58 | F28: 316 | G28: 18.52 | H28: 184 | I28: 12.05 | J28: 172 | K28: 12.55 | L28: 207 | M28: 12.55 | N28: 191 | O28: 14.14 | P28: 81 | Q28: 13.02
A29: Income $75,000 - $99,999 | B29: 41 | C29: 6.81 | D29: 159 | E29: 11.75 | F29: 171 | G29: 10.02 | H29: 108 | I29: 7.07 | J29: 113 | K29: 8.24 | L29: 263 | M29: 15.94 | N29: 196 | O29: 14.51 | P29: 70 | Q29: 11.25
A30: Income $100,000 - $124,999 | B30: 45 | C30: 7.47 | D30: 153 | E30: 11.31 | F30: 218 | G30: 12.78 | H30: 120 | I30: 7.86 | J30: 127 | K30: 9.26 | L30: 164 | M30: 9.94 | N30: 111 | O30: 8.22 | P30: 31 | Q30: 4.98
A31: Income $125,000 - $149,999 | B31: 4 | C31: 0.67 | D31: 163 | E31: 12.05 | F31: 250 | G31: 14.65 | H31: 136 | I31: 8.91 | J31: 109 | K31: 7.95 | L31: 162 | M31: 9.82 | N31: 101 | O31: 7.48 | P31: 32 | Q31: 5.14
A32: Income $150,000 - $199,999 | B32: 20 | C32: 3.32 | D32: 142 | E32: 10.49 | F32: 257 | G32: 15.06 | H32: 288 | I32: 18.86 | J32: 250 | K32: 18.23 | L32: 145 | M32: 8.79 | N32: 91 | O32: 6.74 | P32: 24 | Q32: 3.86
A33: Income $200,000+ | B33: 1 | C33: 0.17 | D33: 65 | E33: 4.8 | F33: 162 | G33: 9.5 | H33: 485 | I33: 31.76 | J33: 400 | K33: 29.18 | L33: 383 | M33: 23.21 | N33: 274 | O33: 20.28 | P33: 98 | Q33: 15.76
A34: Median HH Income | B34: -- | C34: 37818.45 | D34: -- | E34: 75614.12 | F34: -- | G34: 104306.67 | H34: -- | I34: 179656.72 | J34: -- | K34: 141975.19 | L34: -- | M34: 103711.74 | N34: -- | O34: 86801.88 | P34: -- | Q34: 56465.29
A35: Average HH Income | B35: -- | C35: 51629 | D35: -- | E35: 96032 | F35: -- | G35: 115514 | H35: -- | I35: 153898 | J35: -- | K35: 140245 | L35: -- | M35: 123167 | N35: -- | O35: 106732 | P35: -- | Q35: 94875

Sheet PASTE 5 MILE TABS ---->

Sheet 5 mile summary
A1: Pop-Facts® Demographic Quick Facts | Summary
A2: Trade Area: 935 Capitol Landing Rd - 5 mi.
A3: Benchmark: USA
B4: Total | C4: %
A5: Population
A6: 2010 Census | B6: 55087 | C6: 100
A7: 2020 Census | B7: 61454 | C7: 100
A8: 2025 Estimate | B8: 64159 | C8: 100
A9: 2030 Projection | B9: 66125 | C9: 100
A10: Population Growth
A11: Percent Change: 2010 to 2020 | B11: -- | C11: 11.56
A12: Percent Change: 2020 to 2025 | B12: -- | C12: 4.4
A13: Percent Change: 2025 to 2030 | B13: -- | C13: 3.06
A14: Households
A15: 2010 Census | B15: 21273 | C15: 100
A16: 2020 Census | B16: 24331 | C16: 100
A17: 2025 Estimate | B17: 25938 | C17: 100
A18: 2030 Projection | B18: 27010 | C18: 100
A19: Household Growth
A20: Percent Change: 2010 to 2020 | B20: -- | C20: 14.38
A21: Percent Change: 2020 to 2025 | B21: -- | C21: 6.61
A22: Percent Change: 2025 to 2030 | B22: -- | C22: 4.13
A23: Family Households
A24: 2010 Census | B24: 14007 | C24: 100
A25: 2020 Census | B25: 15473 | C25: 100
A26: 2025 Estimate | B26: 16424 | C26: 100
A27: 2030 Projection | B27: 17093 | C27: 100
A28: Family Household Growth
A29: Percent Change: 2010 to 2020 | B29: -- | C29: 10.47
A30: Percent Change: 2020 to 2025 | B30: -- | C30: 6.15
A31: Percent Change: 2025 to 2030 | B31: -- | C31: 4.07

Sheet 5 mile demo quick
A1: Pop-Facts® Demographic Quick Facts | Demographic Quick Facts
A2: Trade Area: 935 Capitol Landing Rd - 5 mi.
A3: Benchmark: USA
B4: Total | C4: %
A5: 2025 Est. Population by Single-Classification Race
A6: White Alone | B6: 41257 | C6: 64.3
A7: Black/African American Alone | B7: 12690 | C7: 19.78
A8: American Indian/Alaskan Native Alone | B8: 189 | C8: 0.29
A9: Asian Alone | B9: 2411 | C9: 3.76
A10: Native Hawaiian/Pacific Islander Alone | B10: 80 | C10: 0.13
A11: Some Other Race Alone | B11: 2031 | C11: 3.17
A12: Two or More Races | B12: 5502 | C12: 8.58
A13: 2025 Est. Population by Ethnicity
A14: Hispanic/Latino | B14: 5500 | C14: 8.57
A15: Not Hispanic/Latino | B15: 58660 | C15: 91.43
A16: 2025 Occupied Housing Units by Tenure
A17: Owner-Occupied | B17: 16196 | C17: 62.44
A18: Renter-Occupied | B18: 9742 | C18: 37.56
A19: Average Household Size | B19: -- | C19: 2.25
A20: 2025 Households by Household Income
A21: Income < $15,000 | B21: 1114 | C21: 4.29
A22: Income $15,000 - $24,999 | B22: 1335 | C22: 5.15
A23: Income $25,000 - $34,999 | B23: 1715 | C23: 6.61
A24: Income $35,000 - $49,999 | B24: 2375 | C24: 9.16
A25: Income $50,000 - $74,999 | B25: 4183 | C25: 16.13
A26: Income $75,000 - $99,999 | B26: 2918 | C26: 11.25
A27: Income $100,000 - $124,999 | B27: 2642 | C27: 10.19
A28: Income $125,000 - $149,999 | B28: 2471 | C28: 9.53
A29: Income $150,000 - $199,999 | B29: 2938 | C29: 11.33
A30: Income $200,000 - $249,999 | B30: 1460 | C30: 5.63
A31: Income $250,000 - $499,999 | B31: 1789 | C31: 6.9
A32: Income $500,000+ | B32: 996 | C32: 3.84
A33: Average Household Income | B33: -- | C33: 129555
A34: Median Household Income | B34: -- | C34: 93777.68
A35: 2025 Est. Median HH Income by Single-Classification Race
A36: White Alone | B36: -- | C36: 102605.64
A37: Black/African American Alone | B37: -- | C37: 63759.21
A38: American Indian/Alaskan Native Alone | B38: -- | C38: 200000.32
A39: Asian Alone | B39: -- | C39: 67105.76
A40: Native Hawaiian/Pacific Islander Alone | B40: -- | C40: 32633.09
...

Sheet 5 mile 2025
A1: Pop-Facts® Effective Buying Income | 2025
A2: Trade Area: 935 Capitol Landing Rd - 5 mi.
A3: Benchmark: USA
B4: Total | C4: %
A5: 2025 Demographic Totals
A6: Population | B6: 64159 | C6: 100
A7: Households | B7: 25938 | C7: 100
A8: Families | B8: 16424 | C8: 100
A9: Group Quarters Population | B9: 6032 | C9: 9.4
A10: Housing Units | B10: 28809 | C10: 100
A11: 2025 Average Household Size
A12: Average Household Size | B12: -- | C12: 2.25
A13: 2025 Median Age
A14: Median Age | B14: -- | C14: 41.66
A15: 2025 Median Household Income
A16: Median Household Income | B16: -- | C16: 93777.68
A17: 2025 Median All Owner-Occupied Housing Value
A18: Median All Owner-Occupied Housing Value | B18: -- | C18: 506354.79
A19: 2025 Est. Households by Effective Buying Income
A20: CY HHs, EBI < $15,000 | B20: 1082 | C20: 4.17
A21: CY HHs, EBI $15,000 - $24,999 | B21: 1408 | C21: 5.43
A22: CY HHs, EBI $25,000 - $34,999 | B22: 1915 | C22: 7.38
A23: CY HHs, EBI $35,000 - $49,999 | B23: 3153 | C23: 12.16
A24: CY HHs, EBI $50,000 - $74,999 | B24: 4838 | C24: 18.65
A25: CY HHs, EBI $75,000 - $99,999 | B25: 3675 | C25: 14.17
A26: CY HHs, EBI $100,000 - $124,999 | B26: 3109 | C26: 11.99
A27: CY HHs, EBI $125,000 - $149,999 | B27: 2069 | C27: 7.98
A28: CY HHs, EBI $150,000 - $199,999 | B28: 2016 | C28: 7.77
A29: CY HHs, EBI $200,000 - $249,999 | B29: 501 | C29: 1.93
A30: CY HHs, EBI $250,000 - $499,999 | B30: 1640 | C30: 6.32
A31: CY HHs, EBI $500,000+ | B31: 531 | C31: 2.05
A32: 2025 Effective Buying Income
A33: Average Effective Buying Income | B33: -- | C33: 108476
A34: Median Effective Buying Income | B34: -- | C34: 78497.63
A35: Aggregate Effective Buying Income | B35: 2813621006 | C35: 108474.86

Sheet 5 mile 2030
A1: Pop-Facts® Effective Buying Income | 2030
A2: Trade Area: 935 Capitol Landing Rd - 5 mi.
A3: Benchmark: USA
B4: Total | C4: %
A5: 2030 Demographic Totals
A6: Population | B6: 66125 | C6: 100
A7: Households | B7: 27010 | C7: 100
A8: Families | B8: 17093 | C8: 100
A9: Group Quarters Population | B9: 6131 | C9: 9.27
A10: Housing Units | B10: 30002 | C10: 100
A11: 2030 Average Household Size
A12: Average Household Size | B12: -- | C12: 2.24
A13: 2030 Median Age
A14: Median Age | B14: -- | C14: 42.84
A15: 2030 Median Household Income
A16: Median Household Income | B16: -- | C16: 103039.89
A17: 2030 Median All Owner-Occupied Housing Value
A18: Median All Owner-Occupied Housing Value | B18: -- | C18: 587125.59
A19: 2030 Proj. Households by Effective Buying Income
A20: FY HHs, EBI < $15,000 | B20: 1048 | C20: 3.88
A21: FY HHs, EBI $15,000 - $24,999 | B21: 1214 | C21: 4.5
A22: FY HHs, EBI $25,000 - $34,999 | B22: 1862 | C22: 6.89
A23: FY HHs, EBI $35,000 - $49,999 | B23: 2949 | C23: 10.92
A24: FY HHs, EBI $50,000 - $74,999 | B24: 4802 | C24: 17.78
A25: FY HHs, EBI $75,000 - $99,999 | B25: 3710 | C25: 13.74
A26: FY HHs, EBI $100,000 - $124,999 | B26: 3113 | C26: 11.53
A27: FY HHs, EBI $125,000 - $149,999 | B27: 2325 | C27: 8.61
A28: FY HHs, EBI $150,000 - $199,999 | B28: 2572 | C28: 9.52
A29: FY HHs, EBI $200,000 - $249,999 | B29: 615 | C29: 2.28
A30: FY HHs, EBI $250,000 - $499,999 | B30: 2080 | C30: 7.7
A31: FY HHs, EBI $500,000+ | B31: 721 | C31: 2.67
A32: 2030 Households by Effective Buying Income
A33: Average Household Effective Buying Income | B33: -- | C33: 119267
A34: Median Household Effective Buying Income | B34: -- | C34: 85279.65
A35: Aggregate Household Effective Buying Income | B35: 3216656480 | C35: 119091.32

Sheet 5 mile age of HHer
A1: Pop-Facts® Household Income By Age of Householder | Income by Age of Householder
A2: Trade Area: 935 Capitol Landing Rd - 5 mi.
A3: Benchmark: USA
B4: Age 15-24 | D4: Age 25-34 | F4: Age 35-44 | H4: Age 45-54 | J4: Age 55-64 | L4: Age 65-74 | N4: Age 75-84 | P4: Age 85+
B5: HHs | C5: % | D5: HHs | E5: % | F5: HHs | G5: % | H5: HHs | I5: % | J5: HHs | K5: % | L5: HHs | M5: % | N5: HHs | O5: % | P5: HHs | Q5: %
A6: 2025 Household Totals
A7: Household Totals | B7: 1150 | C7: 4.43 | D7: 3400 | E7: 13.11 | F7: 3846 | G7: 14.83 | H7: 3518 | I7: 13.56 | J7: 4162 | K7: 16.05 | L7: 4775 | M7: 18.41 | N7: 3605 | O7: 13.9 | P7: 1482 | Q7: 5.71
A8: 2025 Estimate Income/Age
A9: Income Less Than $15,000 | B9: 321 | C9: 27.91 | D9: 96 | E9: 2.82 | F9: 83 | G9: 2.16 | H9: 58 | I9: 1.65 | J9: 110 | K9: 2.64 | L9: 167 | M9: 3.5 | N9: 177 | O9: 4.91 | P9: 102 | Q9: 6.88
A10: Income $15,000 - $24,999 | B10: 89 | C10: 7.74 | D10: 155 | E10: 4.56 | F10: 127 | G10: 3.3 | H10: 115 | I10: 3.27 | J10: 203 | K10: 4.88 | L10: 211 | M10: 4.42 | N10: 268 | O10: 7.43 | P10: 167 | Q10: 11.27
A11: Income $25,000 - $34,999 | B11: 138 | C11: 12 | D11: 200 | E11: 5.88 | F11: 153 | G11: 3.98 | H11: 161 | I11: 4.58 | J11: 247 | K11: 5.93 | L11: 289 | M11: 6.05 | N11: 346 | O11: 9.6 | P11: 180 | Q11: 12.15
A12: Income $35,000 - $49,999 | B12: 201 | C12: 17.48 | D12: 409 | E12: 12.03 | F12: 345 | G12: 8.97 | H12: 212 | I12: 6.03 | J12: 286 | K12: 6.87 | L12: 384 | M12: 8.04 | N12: 365 | O12: 10.13 | P12: 175 | Q12: 11.81
A13: Income $50,000 - $74,999 | B13: 137 | C13: 11.91 | D13: 920 | E13: 27.06 | F13: 874 | G13: 22.73 | H13: 340 | I13: 9.66 | J13: 454 | K13: 10.91 | L13: 697 | M13: 14.6 | N13: 542 | O13: 15.04 | P13: 219 | Q13: 14.78
A14: Income $75,000 - $99,999 | B14: 88 | C14: 7.65 | D14: 512 | E14: 15.06 | F14: 501 | G14: 13.03 | H14: 280 | I14: 7.96 | J14: 343 | K14: 8.24 | L14: 619 | M14: 12.96 | N14: 421 | O14: 11.68 | P14: 155 | Q14: 10.46
A15: Income $100,000 - $124,999 | B15: 146 | C15: 12.7 | D15: 319 | E15: 9.38 | F15: 395 | G15: 10.27 | H15: 367 | I15: 10.43 | J15: 420 | K15: 10.09 | L15: 548 | M15: 11.48 | N15: 344 | O15: 9.54 | P15: 102 | Q15: 6.88
A16: Income $125,000 - $149,999 | B16: 9 | C16: 0.78 | D16: 366 | E16: 10.77 | F16: 550 | G16: 14.3 | H16: 364 | I16: 10.35 | J16: 391 | K16: 9.39 | L16: 443 | M16: 9.28 | N16: 264 | O16: 7.32 | P16: 84 | Q16: 5.67
A17: Income $150,000 - $199,999 | B17: 21 | C17: 1.83 | D17: 259 | E17: 7.62 | F17: 435 | G17: 11.31 | H17: 532 | I17: 15.12 | J17: 550 | K17: 13.21 | L17: 639 | M17: 13.38 | N17: 380 | O17: 10.54 | P17: 122 | Q17: 8.23
A18: Income $200,000+ | B18: 1 | C18: 0.09 | D18: 166 | E18: 4.88 | F18: 382 | G18: 9.93 | H18: 1090 | I18: 30.98 | J18: 1157 | K18: 27.8 | L18: 778 | M18: 16.29 | N18: 495 | O18: 13.73 | P18: 176 | Q18: 11.88
A19: Median HH Income | B19: -- | C19: 36917.76 | D19: -- | E19: 72573.3 | F19: -- | G19: 90843.62 | H19: -- | I19: 140224.21 | J19: -- | K19: 126063.86 | L19: -- | M19: 100873.37 | N19: -- | O19: 80573.88 | P19: -- | Q19: 62265.04
A20: Average HH Income | B20: -- | C20: 50378 | D20: -- | E20: 98658 | F20: -- | G20: 115087 | H20: -- | I20: 152101 | J20: -- | K20: 135247 | L20: -- | M20: 113224 | N20: -- | O20: 95132 | P20: -- | Q20: 82034
A21: 2030 Household Totals
A22: Household Totals | B22: 1103 | C22: 4.08 | D22: 3298 | E22: 12.21 | F22: 4070 | G22: 15.07 | H22: 3883 | I22: 14.38 | J22: 3737 | K22: 13.84 | L22: 5018 | M22: 18.58 | N22: 4280 | O22: 15.85 | P22: 1621 | Q22: 6
A23: 2030 Projection Income/Age
A24: Income Less Than $15,000 | B24: 290 | C24: 26.29 | D24: 95 | E24: 2.88 | F24: 83 | G24: 2.04 | H24: 57 | I24: 1.47 | J24: 89 | K24: 2.38 | L24: 154 | M24: 3.07 | N24: 201 | O24: 4.7 | P24: 109 | Q24: 6.72
A25: Income $15,000 - $24,999 | B25: 71 | C25: 6.44 | D25: 123 | E25: 3.73 | F25: 114 | G25: 2.8 | H25: 99 | I25: 2.55 | J25: 140 | K25: 3.75 | L25: 182 | M25: 3.63 | N25: 263 | O25: 6.14 | P25: 151 | Q25: 9.31
A26: Income $25,000 - $34,999 | B26: 147 | C26: 13.33 | D26: 180 | E26: 5.46 | F26: 155 | G26: 3.81 | H26: 161 | I26: 4.15 | J26: 198 | K26: 5.3 | L26: 263 | M26: 5.24 | N26: 359 | O26: 8.39 | P26: 185 | Q26: 11.41
A27: Income $35,000 - $49,999 | B27: 181 | C27: 16.41 | D27: 376 | E27: 11.4 | F27: 330 | G27: 8.11 | H27: 198 | I27: 5.1 | J27: 204 | K27: 5.46 | L27: 378 | M27: 7.53 | N27: 403 | O27: 9.42 | P27: 180 | Q27: 11.1
A28: Income $50,000 - $74,999 | B28: 139 | C28: 12.6 | D28: 860 | E28: 26.08 | F28: 828 | G28: 20.34 | H28: 309 | I28: 7.96 | J28: 339 | K28: 9.07 | L28: 692 | M28: 13.79 | N28: 618 | O28: 14.44 | P28: 228 | Q28: 14.06
A29: Income $75,000 - $99,999 | B29: 90 | C29: 8.16 | D29: 520 | E29: 15.77 | F29: 558 | G29: 13.71 | H29: 289 | I29: 7.44 | J29: 298 | K29: 7.97 | L29: 631 | M29: 12.57 | N29: 484 | O29: 11.31 | P29: 166 | Q29: 10.24
A30: Income $100,000 - $124,999 | B30: 148 | C30: 13.42 | D30: 294 | E30: 8.91 | F30: 420 | G30: 10.32 | H30: 359 | I30: 9.24 | J30: 346 | K30: 9.26 | L30: 544 | M30: 10.84 | N30: 401 | O30: 9.37 | P30: 112 | Q30: 6.91
A31: Income $125,000 - $149,999 | B31: 14 | C31: 1.27 | D31: 345 | E31: 10.46 | F31: 526 | G31: 12.92 | H31: 374 | I31: 9.63 | J31: 327 | K31: 8.75 | L31: 446 | M31: 8.89 | N31: 306 | O31: 7.15 | P31: 92 | Q31: 5.67
A32: Income $150,000 - $199,999 | B32: 20 | C32: 1.81 | D32: 284 | E32: 8.61 | F32: 546 | G32: 13.41 | H32: 612 | I32: 15.76 | J32: 529 | K32: 14.16 | L32: 697 | M32: 13.89 | N32: 471 | O32: 11.01 | P32: 140 | Q32: 8.64
A33: Income $200,000+ | B33: 2 | C33: 0.18 | D33: 223 | E33: 6.76 | F33: 510 | G33: 12.53 | H33: 1424 | I33: 36.67 | J33: 1268 | K33: 33.93 | L33: 1031 | M33: 20.55 | N33: 772 | O33: 18.04 | P33: 258 | Q33: 15.92
A34: Median HH Income | B34: -- | C34: 38172.5 | D34: -- | E34: 75599.13 | F34: -- | G34: 98279.7 | H34: -- | I34: 184849.14 | J34: -- | K34: 144261.42 | L34: -- | M34: 109117.33 | N34: -- | O34: 89588.07 | P34: -- | Q34: 69700.58
A35: Average HH Income | B35: -- | C35: 53178 | D35: -- | E35: 100132 | F35: -- | G35: 125641 | H35: -- | I35: 165004 | J35: -- | K35: 146656 | L35: -- | M35: 122125 | N35: -- | O35: 103586 | P35: -- | Q35: 90331

Sheet Sheet1
